Workbook

Sheet 📊 Dashboard
B1: ORGANICS BY AWANFARM — MANAGEMENT DASHBOARD
B2: All figures are automatically calculated from the Monthly Subscriptions, Weekly Subscriptions, and Expense Tracker sheets.
B4: SELECT MONTH FOR FILTERED VIEW: | D4: May | E4: ← Change this cell to filter KPIs by month
B6: OVERALL BUSINESS SUMMARY (All Months Combined)
B7: Total Monthly Subscription Income | C7: Total Weekly Subscription Income | D7: Total Combined Income | E7: Total Expenses | F7: Total Payment Received | G7: Total Pending Payments | H7: Net Profit (Income − Expenses) | I7: Total Active Customers
B8: ='Monthly Subscriptions'!H55 -> 40920 | C8: ='Weekly Subscriptions'!J55 -> 56440 | D8: ='Monthly Subscriptions'!H55+'Weekly Subscriptions'!J55 -> 97360 | E8: =SUM('Expense Tracker'!F5:F84) -> 14770 | F8: ='Monthly Subscriptions'!I55+'Weekly Subscriptions'!K55 -> 0 | G8: ='Monthly Subscriptions'!J55+'Weekly Subscriptions'!L55 -> 97360 | H8: ='Monthly Subscriptions'!H55+'Weekly Subscriptions'!J55-SUM('Expense Tracker'!F5:F84) -> 82590 | I8: =COUNTA('Monthly Subscriptions'!C5:C54)+COUNTA('Weekly Subscriptions'!C5:C54) -> 8
B9: PKR | C9: PKR | D9: PKR | E9: PKR | F9: PKR | G9: PKR | H9: PKR | I9: customers
B11: FILTERED SUMMARY — Month: (see D4 selector above)
B12: Monthly Subs Income (Selected Mo.) | C12: Weekly Subs Income (Selected Mo.) | D12: Total Income (Selected Month) | E12: Expenses (Selected Month) | F12: Payment Received (Selected Month) | G12: Pending Amount (Selected Month) | H12: Net Profit (Selected Month) | I12: Active Customers (Selected Month)
B13: =SUMIF('Monthly Subscriptions'!B5:B54,D4,'Monthly Subscriptions'!H5:H54) -> 40920 | C13: =SUMIF('Weekly Subscriptions'!B5:B54,D4,'Weekly Subscriptions'!J5:J54) -> 56440 | D13: =SUMIF('Monthly Subscriptions'!B5:B54,D4,'Monthly Subscriptions'!H5:H54)+SUMIF('Weekly Subscriptions'!B5:B54,D4,'Weekly Subscriptions'!J5:J54) -> 97360 | E13: =SUMIF('Expense Tracker'!B5:B84,D4,'Expense Tracker'!F5:F84) -> 13770 | F13: =SUMIF('Monthly Subscriptions'!B5:B54,D4,'Monthly Subscriptions'!I5:I54)+SUMIF('Weekly Subscriptions'!B5:B54,D4,'Weekly Subscriptions'!K5:K54) -> 0 | G13: =SUMIF('Monthly Subscriptions'!B5:B54,D4,'Monthly Subscriptions'!J5:J54)+SUMIF('Weekly Subscriptions'!B5:B54,D4,'Weekly Subscriptions'!L5:L54) -> 97360 | H13: =SUMIF('Monthly Subscriptions'!B5:B54,D4,'Monthly Subscriptions'!H5:H54)+SUMIF('Weekly Subscriptions'!B5:B54,D4,'Weekly Subscriptions'!J5:J54)-SUMIF('Expense Tracker'!B5:B84,D4,'Expense Tracker'!F5:F84) -> 83590 | I13: =COUNTIF('Monthly Subscriptions'!B5:B54,D4)+COUNTIF('Weekly Subscriptions'!B5:B54,D4) -> 9
B14: PKR | C14: PKR | D14: PKR | E14: PKR | F14: PKR | G14: PKR | H14: PKR | I14: customers
B16: MONTH-BY-MONTH PERFORMANCE BREAKDOWN
B17: Month | C17: Monthly Sub Income (PKR) | D17: Weekly Sub Income (PKR) | E17: Total Income (PKR) | F17: Total Expenses (PKR) | G17: Net Profit (PKR) | H17: Pending Payments (PKR) | I17: Customers (Count)
B18: January | C18: =SUMIF('Monthly Subscriptions'!B5:B54,B18,'Monthly Subscriptions'!H5:H54) -> 0 | D18: =SUMIF('Weekly Subscriptions'!B5:B54,B18,'Weekly Subscriptions'!J5:J54) -> 0 | E18: =C18+D18 -> 0 | F18: =SUMIF('Expense Tracker'!B5:B84,B18,'Expense Tracker'!F5:F84) -> 0 | G18: =E18-F18 -> 0 | H18: =SUMIF('Monthly Subscriptions'!B5:B54,B18,'Monthly Subscriptions'!J5:J54)+SUMIF('Weekly Subscriptions'!B5:B54,B18,'Weekly Subscriptions'!L5:L54) -> 0 | I18: =COUNTIF('Monthly Subscriptions'!B5:B54,B18)+COUNTIF('Weekly Subscriptions'!B5:B54,B18) -> 0
B19: February | C19: =SUMIF('Monthly Subscriptions'!B5:B54,B19,'Monthly Subscriptions'!H5:H54) -> 0 | D19: =SUMIF('Weekly Subscriptions'!B5:B54,B19,'Weekly Subscriptions'!J5:J54) -> 0 | E19: =C19+D19 -> 0 | F19: =SUMIF('Expense Tracker'!B5:B84,B19,'Expense Tracker'!F5:F84) -> 0 | G19: =E19-F19 -> 0 | H19: =SUMIF('Monthly Subscriptions'!B5:B54,B19,'Monthly Subscriptions'!J5:J54)+SUMIF('Weekly Subscriptions'!B5:B54,B19,'Weekly Subscriptions'!L5:L54) -> 0 | I19: =COUNTIF('Monthly Subscriptions'!B5:B54,B19)+COUNTIF('Weekly Subscriptions'!B5:B54,B19) -> 0
B20: March | C20: =SUMIF('Monthly Subscriptions'!B5:B54,B20,'Monthly Subscriptions'!H5:H54) -> 0 | D20: =SUMIF('Weekly Subscriptions'!B5:B54,B20,'Weekly Subscriptions'!J5:J54) -> 0 | E20: =C20+D20 -> 0 | F20: =SUMIF('Expense Tracker'!B5:B84,B20,'Expense Tracker'!F5:F84) -> 0 | G20: =E20-F20 -> 0 | H20: =SUMIF('Monthly Subscriptions'!B5:B54,B20,'Monthly Subscriptions'!J5:J54)+SUMIF('Weekly Subscriptions'!B5:B54,B20,'Weekly Subscriptions'!L5:L54) -> 0 | I20: =COUNTIF('Monthly Subscriptions'!B5:B54,B20)+COUNTIF('Weekly Subscriptions'!B5:B54,B20) -> 0
B21: April | C21: =SUMIF('Monthly Subscriptions'!B5:B54,B21,'Monthly Subscriptions'!H5:H54) -> 0 | D21: =SUMIF('Weekly Subscriptions'!B5:B54,B21,'Weekly Subscriptions'!J5:J54) -> 0 | E21: =C21+D21 -> 0 | F21: =SUMIF('Expense Tracker'!B5:B84,B21,'Expense Tracker'!F5:F84) -> 0 | G21: =E21-F21 -> 0 | H21: =SUMIF('Monthly Subscriptions'!B5:B54,B21,'Monthly Subscriptions'!J5:J54)+SUMIF('Weekly Subscriptions'!B5:B54,B21,'Weekly Subscriptions'!L5:L54) -> 0 | I21: =COUNTIF('Monthly Subscriptions'!B5:B54,B21)+COUNTIF('Weekly Subscriptions'!B5:B54,B21) -> 0
B22: May | C22: =SUMIF('Monthly Subscriptions'!B5:B54,B22,'Monthly Subscriptions'!H5:H54) -> 40920 | D22: =SUMIF('Weekly Subscriptions'!B5:B54,B22,'Weekly Subscriptions'!J5:J54) -> 56440 | E22: =C22+D22 -> 97360 | F22: =SUMIF('Expense Tracker'!B5:B84,B22,'Expense Tracker'!F5:F84) -> 13770 | G22: =E22-F22 -> 83590 | H22: =SUMIF('Monthly Subscriptions'!B5:B54,B22,'Monthly Subscriptions'!J5:J54)+SUMIF('Weekly Subscriptions'!B5:B54,B22,'Weekly Subscriptions'!L5:L54) -> 97360 | I22: =COUNTIF('Monthly Subscriptions'!B5:B54,B22)+COUNTIF('Weekly Subscriptions'!B5:B54,B22) -> 9
B23: June | C23: =SUMIF('Monthly Subscriptions'!B5:B54,B23,'Monthly Subscriptions'!H5:H54) -> 0 | D23: =SUMIF('Weekly Subscriptions'!B5:B54,B23,'Weekly Subscriptions'!J5:J54) -> 0 | E23: =C23+D23 -> 0 | F23: =SUMIF('Expense Tracker'!B5:B84,B23,'Expense Tracker'!F5:F84) -> 0 | G23: =E23-F23 -> 0 | H23: =SUMIF('Monthly Subscriptions'!B5:B54,B23,'Monthly Subscriptions'!J5:J54)+SUMIF('Weekly Subscriptions'!B5:B54,B23,'Weekly Subscriptions'!L5:L54) -> 0 | I23: =COUNTIF('Monthly Subscriptions'!B5:B54,B23)+COUNTIF('Weekly Subscriptions'!B5:B54,B23) -> 0
B24: July | C24: =SUMIF('Monthly Subscriptions'!B5:B54,B24,'Monthly Subscriptions'!H5:H54) -> 0 | D24: =SUMIF('Weekly Subscriptions'!B5:B54,B24,'Weekly Subscriptions'!J5:J54) -> 0 | E24: =C24+D24 -> 0 | F24: =SUMIF('Expense Tracker'!B5:B84,B24,'Expense Tracker'!F5:F84) -> 0 | G24: =E24-F24 -> 0 | H24: =SUMIF('Monthly Subscriptions'!B5:B54,B24,'Monthly Subscriptions'!J5:J54)+SUMIF('Weekly Subscriptions'!B5:B54,B24,'Weekly Subscriptions'!L5:L54) -> 0 | I24: =COUNTIF('Monthly Subscriptions'!B5:B54,B24)+COUNTIF('Weekly Subscriptions'!B5:B54,B24) -> 0
B25: August | C25: =SUMIF('Monthly Subscriptions'!B5:B54,B25,'Monthly Subscriptions'!H5:H54) -> 0 | D25: =SUMIF('Weekly Subscriptions'!B5:B54,B25,'Weekly Subscriptions'!J5:J54) -> 0 | E25: =C25+D25 -> 0 | F25: =SUMIF('Expense Tracker'!B5:B84,B25,'Expense Tracker'!F5:F84) -> 0 | G25: =E25-F25 -> 0 | H25: =SUMIF('Monthly Subscriptions'!B5:B54,B25,'Monthly Subscriptions'!J5:J54)+SUMIF('Weekly Subscriptions'!B5:B54,B25,'Weekly Subscriptions'!L5:L54) -> 0 | I25: =COUNTIF('Monthly Subscriptions'!B5:B54,B25)+COUNTIF('Weekly Subscriptions'!B5:B54,B25) -> 0
B26: September | C26: =SUMIF('Monthly Subscriptions'!B5:B54,B26,'Monthly Subscriptions'!H5:H54) -> 0 | D26: =SUMIF('Weekly Subscriptions'!B5:B54,B26,'Weekly Subscriptions'!J5:J54) -> 0 | E26: =C26+D26 -> 0 | F26: =SUMIF('Expense Tracker'!B5:B84,B26,'Expense Tracker'!F5:F84) -> 0 | G26: =E26-F26 -> 0 | H26: =SUMIF('Monthly Subscriptions'!B5:B54,B26,'Monthly Subscriptions'!J5:J54)+SUMIF('Weekly Subscriptions'!B5:B54,B26,'Weekly Subscriptions'!L5:L54) -> 0 | I26: =COUNTIF('Monthly Subscriptions'!B5:B54,B26)+COUNTIF('Weekly Subscriptions'!B5:B54,B26) -> 0
B27: October | C27: =SUMIF('Monthly Subscriptions'!B5:B54,B27,'Monthly Subscriptions'!H5:H54) -> 0 | D27: =SUMIF('Weekly Subscriptions'!B5:B54,B27,'Weekly Subscriptions'!J5:J54) -> 0 | E27: =C27+D27 -> 0 | F27: =SUMIF('Expense Tracker'!B5:B84,B27,'Expense Tracker'!F5:F84) -> 0 | G27: =E27-F27 -> 0 | H27: =SUMIF('Monthly Subscriptions'!B5:B54,B27,'Monthly Subscriptions'!J5:J54)+SUMIF('Weekly Subscriptions'!B5:B54,B27,'Weekly Subscriptions'!L5:L54) -> 0 | I27: =COUNTIF('Monthly Subscriptions'!B5:B54,B27)+COUNTIF('Weekly Subscriptions'!B5:B54,B27) -> 0
B28: November | C28: =SUMIF('Monthly Subscriptions'!B5:B54,B28,'Monthly Subscriptions'!H5:H54) -> 0 | D28: =SUMIF('Weekly Subscriptions'!B5:B54,B28,'Weekly Subscriptions'!J5:J54) -> 0 | E28: =C28+D28 -> 0 | F28: =SUMIF('Expense Tracker'!B5:B84,B28,'Expense Tracker'!F5:F84) -> 0 | G28: =E28-F28 -> 0 | H28: =SUMIF('Monthly Subscriptions'!B5:B54,B28,'Monthly Subscriptions'!J5:J54)+SUMIF('Weekly Subscriptions'!B5:B54,B28,'Weekly Subscriptions'!L5:L54) -> 0 | I28: =COUNTIF('Monthly Subscriptions'!B5:B54,B28)+COUNTIF('Weekly Subscriptions'!B5:B54,B28) -> 0
B29: December | C29: =SUMIF('Monthly Subscriptions'!B5:B54,B29,'Monthly Subscriptions'!H5:H54) -> 0 | D29: =SUMIF('Weekly Subscriptions'!B5:B54,B29,'Weekly Subscriptions'!J5:J54) -> 0 | E29: =C29+D29 -> 0 | F29: =SUMIF('Expense Tracker'!B5:B84,B29,'Expense Tracker'!F5:F84) -> 0 | G29: =E29-F29 -> 0 | H29: =SUMIF('Monthly Subscriptions'!B5:B54,B29,'Monthly Subscriptions'!J5:J54)+SUMIF('Weekly Subscriptions'!B5:B54,B29,'Weekly Subscriptions'!L5:L54) -> 0 | I29: =COUNTIF('Monthly Subscriptions'!B5:B54,B29)+COUNTIF('Weekly Subscriptions'!B5:B54,B29) -> 0
B30: FULL YEAR TOTAL | C30: =SUM(C18:C29) -> 40920 | D30: =SUM(D18:D29) -> 56440 | E30: =SUM(E18:E29) -> 97360 | F30: =SUM(F18:F29) -> 13770 | G30: =SUM(G18:G29) -> 83590 | H30: =SUM(H18:H29) -> 97360 | I30: =SUM(I18:I29) -> 9
B32: 📌 HOW TO USE THIS WORKBOOK
B33: 1. MONTHLY SUBSCRIPTIONS tab → Add customer name, set Month, enter daily Qty & Rate. Cost and Status are auto-calculated.
B34: 2. WEEKLY SUBSCRIPTIONS tab → Enter Month, delivery days (text), Qty/delivery, Rate, and deliveries per week. Monthly total is auto-calculated.
B35: 3. EXPENSE TRACKER tab → Log each expense with Date, Month, Type & Amount. Monthly and category summaries update automatically.
B36: 4. DASHBOARD → Change cell D4 (Month Selector) to see filtered KPIs for any specific month.
B37: 5. ADDING CUSTOMERS → Simply type in the next empty row. All formulas in formula columns auto-extend when rows are filled.
B38: 6. PAYMENT TRACKING → Enter 'Payment Received' amount; Pending Amount and Status update automatically. Green=Paid, Yellow=Partial, Red=Unpaid.
B39: 7. MONTH-END ARCHIVE → Save a copy each month (e.g. 'Milk_April_2026.xlsx') and clear next month's payment columns for fresh tracking.

Sheet Monthly Subscriptions
A1: MONTHLY SUBSCRIPTION LEDGER — Daily Delivery Customers
A2: Customers who receive milk daily and pay monthly. Filter by Month column. Blue cells = enter data. Black cells = auto-calculated.
A3: 🔵 Enter Data | B3: ⬛ Auto Calc | C3: 🟢 Paid | D3: 🔴 Unpaid
A4: # | B4: Month | C4: Customer Name / House No | D4: Daily Qty (Ltrs/Btls) | E4: Rate (PKR/Unit) | F4: Days in Month | G4: Total Monthly Milk (Units) | H4: Total Monthly Cost (PKR) | I4: Payment Received (PKR) | J4: Pending Amount (PKR) | K4: Payment Status | L4: Notes
A5: 1 | B5: May | C5: 69 E Model Town | D5: 4 | E5: 330 | F5: =IFERROR(switch(B5,"January",31,"February",28,"March",31,"April",30,"May",31,"June",30,"July",31,"August",31,"September",30,"October",31,"November",30,"December",31,30),"") -> 31 | G5: =IF(OR(D5="",F5=""),"",D5*F5) -> 124 | H5: =IF(OR(G5="",E5=""),"",G5*E5) -> 40920 | J5: =IF(H5="","",H5-IF(I5="",0,I5)) -> 40920 | K5: Paid
A6: 2 | B6: May | F6: =IFERROR(switch(B6,"January",31,"February",28,"March",31,"April",30,"May",31,"June",30,"July",31,"August",31,"September",30,"October",31,"November",30,"December",31,30),"") -> 31 | G6: =IF(OR(D6="",F6=""),"",D6*F6) | H6: =IF(OR(G6="",E6=""),"",G6*E6) | J6: =IF(H6="","",H6-IF(I6="",0,I6)) | K6: =IF(H6="","",IF(I6="","Unpaid",IF(I6>=H6,"Paid",IF(I6>0,"Partial","Unpaid"))))
A7: 3 | F7: =IFERROR(switch(B7,"January",31,"February",28,"March",31,"April",30,"May",31,"June",30,"July",31,"August",31,"September",30,"October",31,"November",30,"December",31,30),"") -> 30 | G7: =IF(OR(D7="",F7=""),"",D7*F7) | H7: =IF(OR(G7="",E7=""),"",G7*E7) | J7: =IF(H7="","",H7-IF(I7="",0,I7)) | K7: =IF(H7="","",IF(I7="","Unpaid",IF(I7>=H7,"Paid",IF(I7>0,"Partial","Unpaid"))))
A8: 4 | F8: =IFERROR(switch(B8,"January",31,"February",28,"March",31,"April",30,"May",31,"June",30,"July",31,"August",31,"September",30,"October",31,"November",30,"December",31,30),"") -> 30 | G8: =IF(OR(D8="",F8=""),"",D8*F8) | H8: =IF(OR(G8="",E8=""),"",G8*E8) | J8: =IF(H8="","",H8-IF(I8="",0,I8)) | K8: =IF(H8="","",IF(I8="","Unpaid",IF(I8>=H8,"Paid",IF(I8>0,"Partial","Unpaid"))))
A9: 5 | F9: =IFERROR(switch(B9,"January",31,"February",28,"March",31,"April",30,"May",31,"June",30,"July",31,"August",31,"September",30,"October",31,"November",30,"December",31,30),"") -> 30 | G9: =IF(OR(D9="",F9=""),"",D9*F9) | H9: =IF(OR(G9="",E9=""),"",G9*E9) | J9: =IF(H9="","",H9-IF(I9="",0,I9)) | K9: =IF(H9="","",IF(I9="","Unpaid",IF(I9>=H9,"Paid",IF(I9>0,"Partial","Unpaid"))))
A10: 6 | F10: =IFERROR(switch(B10,"January",31,"February",28,"March",31,"April",30,"May",31,"June",30,"July",31,"August",31,"September",30,"October",31,"November",30,"December",31,30),"") -> 30 | G10: =IF(OR(D10="",F10=""),"",D10*F10) | H10: =IF(OR(G10="",E10=""),"",G10*E10) | J10: =IF(H10="","",H10-IF(I10="",0,I10)) | K10: =IF(H10="","",IF(I10="","Unpaid",IF(I10>=H10,"Paid",IF(I10>0,"Partial","Unpaid"))))
A11: 7 | F11: =IFERROR(switch(B11,"January",31,"February",28,"March",31,"April",30,"May",31,"June",30,"July",31,"August",31,"September",30,"October",31,"November",30,"December",31,30),"") -> 30 | G11: =IF(OR(D11="",F11=""),"",D11*F11) | H11: =IF(OR(G11="",E11=""),"",G11*E11) | J11: =IF(H11="","",H11-IF(I11="",0,I11)) | K11: =IF(H11="","",IF(I11="","Unpaid",IF(I11>=H11,"Paid",IF(I11>0,"Partial","Unpaid"))))
A12: 8 | F12: =IFERROR(switch(B12,"January",31,"February",28,"March",31,"April",30,"May",31,"June",30,"July",31,"August",31,"September",30,"October",31,"November",30,"December",31,30),"") -> 30 | G12: =IF(OR(D12="",F12=""),"",D12*F12) | H12: =IF(OR(G12="",E12=""),"",G12*E12) | J12: =IF(H12="","",H12-IF(I12="",0,I12)) | K12: =IF(H12="","",IF(I12="","Unpaid",IF(I12>=H12,"Paid",IF(I12>0,"Partial","Unpaid"))))
A13: 9 | F13: =IFERROR(switch(B13,"January",31,"February",28,"March",31,"April",30,"May",31,"June",30,"July",31,"August",31,"September",30,"October",31,"November",30,"December",31,30),"") -> 30 | G13: =IF(OR(D13="",F13=""),"",D13*F13) | H13: =IF(OR(G13="",E13=""),"",G13*E13) | J13: =IF(H13="","",H13-IF(I13="",0,I13)) | K13: =IF(H13="","",IF(I13="","Unpaid",IF(I13>=H13,"Paid",IF(I13>0,"Partial","Unpaid"))))
A14: 10 | F14: =IFERROR(switch(B14,"January",31,"February",28,"March",31,"April",30,"May",31,"June",30,"July",31,"August",31,"September",30,"October",31,"November",30,"December",31,30),"") -> 30 | G14: =IF(OR(D14="",F14=""),"",D14*F14) | H14: =IF(OR(G14="",E14=""),"",G14*E14) | J14: =IF(H14="","",H14-IF(I14="",0,I14)) | K14: =IF(H14="","",IF(I14="","Unpaid",IF(I14>=H14,"Paid",IF(I14>0,"Partial","Unpaid"))))
A15: 11 | F15: =IFERROR(switch(B15,"January",31,"February",28,"March",31,"April",30,"May",31,"June",30,"July",31,"August",31,"September",30,"October",31,"November",30,"December",31,30),"") -> 30 | G15: =IF(OR(D15="",F15=""),"",D15*F15) | H15: =IF(OR(G15="",E15=""),"",G15*E15) | J15: =IF(H15="","",H15-IF(I15="",0,I15)) | K15: =IF(H15="","",IF(I15="","Unpaid",IF(I15>=H15,"Paid",IF(I15>0,"Partial","Unpaid"))))
A16: 12 | F16: =IFERROR(switch(B16,"January",31,"February",28,"March",31,"April",30,"May",31,"June",30,"July",31,"August",31,"September",30,"October",31,"November",30,"December",31,30),"") -> 30 | G16: =IF(OR(D16="",F16=""),"",D16*F16) | H16: =IF(OR(G16="",E16=""),"",G16*E16) | J16: =IF(H16="","",H16-IF(I16="",0,I16)) | K16: =IF(H16="","",IF(I16="","Unpaid",IF(I16>=H16,"Paid",IF(I16>0,"Partial","Unpaid"))))
A17: 13 | F17: =IFERROR(switch(B17,"January",31,"February",28,"March",31,"April",30,"May",31,"June",30,"July",31,"August",31,"September",30,"October",31,"November",30,"December",31,30),"") -> 30 | G17: =IF(OR(D17="",F17=""),"",D17*F17) | H17: =IF(OR(G17="",E17=""),"",G17*E17) | J17: =IF(H17="","",H17-IF(I17="",0,I17)) | K17: =IF(H17="","",IF(I17="","Unpaid",IF(I17>=H17,"Paid",IF(I17>0,"Partial","Unpaid"))))
A18: 14 | F18: =IFERROR(switch(B18,"January",31,"February",28,"March",31,"April",30,"May",31,"June",30,"July",31,"August",31,"September",30,"October",31,"November",30,"December",31,30),"") -> 30 | G18: =IF(OR(D18="",F18=""),"",D18*F18) | H18: =IF(OR(G18="",E18=""),"",G18*E18) | J18: =IF(H18="","",H18-IF(I18="",0,I18)) | K18: =IF(H18="","",IF(I18="","Unpaid",IF(I18>=H18,"Paid",IF(I18>0,"Partial","Unpaid"))))
... A54: 50 | F54: =IFERROR(switch(B54,"January",31,"February",28,"March",31,"April",30,"May",31,"June",30,"July",31,"August",31,"September",30,"October",31,"November",30,"December",31,30),"") -> 30 | G54: =IF(OR(D54="",F54=""),"",D54*F54) | H54: =IF(OR(G54="",E54=""),"",G54*E54) | J54: =IF(H54="","",H54-IF(I54="",0,I54)) | K54: =IF(H54="","",IF(I54="","Unpaid",IF(I54>=H54,"Paid",IF(I54>0,"Partial","Unpaid"))))
A55: TOTALS | H55: =SUM(H5:H54) -> 40920 | I55: =SUM(I5:I54) -> 0 | J55: =SUM(J5:J54) -> 40920

Sheet Weekly Subscriptions
A1: WEEKLY SUBSCRIPTION LEDGER
A2: Customers receiving milk 2–3 times/week. Enter delivery days (e.g. Mon,Wed,Fri). System auto-calculates total monthly deliveries and cost.
A3: 🔵 Enter Data | B3: ⬛ Auto Calc | C3: 🟢 Paid | D3: 🟡 Partial | E3: 🔴 Unpaid
A4: # | B4: Month | C4: Customer Name / House No | D4: Address (Optional) | E4: Delivery Days (e.g. Mon,Wed,Fri) | F4: Qty per Delivery | G4: Rate per Delivery (PKR) | H4: Deliveries per Week | I4: Total Monthly Deliveries | J4: Total Monthly Cost (PKR) | K4: Payment Received (PKR) | L4: Pending Amount (PKR) | M4: Payment Status
A5: 1 | B5: May | C5: State Life | E5: Saturday | F5: 4 | G5: 380 | H5: 1 | I5: =IFERROR(IF(OR(H5="",B5=""),"",ROUND(H5*switch(B5,"January",4.43,"February",4,"March",4.43,"April",4.33,"May",4.43,"June",4.33,"July",4.43,"August",4.43,"September",4.33,"October",4.43,"November",4.33,"December",4.43,4.33),0)),"") -> 4 | J5: 6080 | L5: =IF(J5="","",J5-IF(K5="",0,K5)) -> 6080 | M5: =IF(J5="","",IF(K5="","Unpaid",IF(K5>=J5,"Paid",IF(K5>0,"Partial","Unpaid")))) -> Unpaid
A6: 2 | B6: May | C6: 47L Model Town | E6: Mon to Fri | F6: 2 | G6: 330 | H6: 5 | I6: =IFERROR(IF(OR(H6="",B6=""),"",ROUND(H6*switch(B6,"January",4.43,"February",4,"March",4.43,"April",4.33,"May",4.43,"June",4.33,"July",4.43,"August",4.43,"September",4.33,"October",4.43,"November",4.33,"December",4.43,4.33),0)),"") -> 22 | J6: =IF(OR(I6="",F6="",G6=""),"",I6*F6*G6) -> 14520 | L6: =IF(J6="","",J6-IF(K6="",0,K6)) -> 14520 | M6: =IF(J6="","",IF(K6="","Unpaid",IF(K6>=J6,"Paid",IF(K6>0,"Partial","Unpaid")))) -> Unpaid
A7: 3 | B7: May | C7: Iqbal Town 654 Kashmir Block | E7: Saturday | F7: 4 | G7: 330 | H7: 1 | I7: =IFERROR(IF(OR(H7="",B7=""),"",ROUND(H7*switch(B7,"January",4.43,"February",4,"March",4.43,"April",4.33,"May",4.43,"June",4.33,"July",4.43,"August",4.43,"September",4.33,"October",4.43,"November",4.33,"December",4.43,4.33),0)),"") -> 4 | J7: =IF(OR(I7="",F7="",G7=""),"",I7*F7*G7) -> 5280 | L7: =IF(J7="","",J7-IF(K7="",0,K7)) -> 5280 | M7: =IF(J7="","",IF(K7="","Unpaid",IF(K7>=J7,"Paid",IF(K7>0,"Partial","Unpaid")))) -> Unpaid
A8: 4 | B8: May | C8: Dental Medical Collage | E8: Saturday | F8: 2 | G8: 380 | H8: 1 | I8: =IFERROR(IF(OR(H8="",B8=""),"",ROUND(H8*switch(B8,"January",4.43,"February",4,"March",4.43,"April",4.33,"May",4.43,"June",4.33,"July",4.43,"August",4.43,"September",4.33,"October",4.43,"November",4.33,"December",4.43,4.33),0)),"") -> 4 | J8: =IF(OR(I8="",F8="",G8=""),"",I8*F8*G8) -> 3040 | L8: =IF(J8="","",J8-IF(K8="",0,K8)) -> 3040 | M8: =IF(J8="","",IF(K8="","Unpaid",IF(K8>=J8,"Paid",IF(K8>0,"Partial","Unpaid")))) -> Unpaid
A9: 5 | B9: May | C9: G2 Calvary Groung | F9: 1 | G9: 430 | I9: 9 | J9: =IF(OR(I9="",F9="",G9=""),"",I9*F9*G9) -> 3870 | L9: =IF(J9="","",J9-IF(K9="",0,K9)) -> 3870 | M9: =IF(J9="","",IF(K9="","Unpaid",IF(K9>=J9,"Paid",IF(K9>0,"Partial","Unpaid")))) -> Unpaid
A10: 6 | B10: May | C10: 33 D Model Town | I10: =IFERROR(IF(OR(H10="",B10=""),"",ROUND(H10*switch(B10,"January",4.43,"February",4,"March",4.43,"April",4.33,"May",4.43,"June",4.33,"July",4.43,"August",4.43,"September",4.33,"October",4.43,"November",4.33,"December",4.43,4.33),0)),"") | J10: 1290 | L10: =IF(J10="","",J10-IF(K10="",0,K10)) -> 1290 | M10: =IF(J10="","",IF(K10="","Unpaid",IF(K10>=J10,"Paid",IF(K10>0,"Partial","Unpaid")))) -> Unpaid
A11: 7 | B11: May | C11: Bahria Sector B | G11: 430 | I11: 13 | J11: 22360 | L11: =IF(J11="","",J11-IF(K11="",0,K11)) -> 22360 | M11: =IF(J11="","",IF(K11="","Unpaid",IF(K11>=J11,"Paid",IF(K11>0,"Partial","Unpaid")))) -> Unpaid
A12: 8 | I12: =IFERROR(IF(OR(H12="",B12=""),"",ROUND(H12*switch(B12,"January",4.43,"February",4,"March",4.43,"April",4.33,"May",4.43,"June",4.33,"July",4.43,"August",4.43,"September",4.33,"October",4.43,"November",4.33,"December",4.43,4.33),0)),"") | J12: =IF(OR(I12="",F12="",G12=""),"",I12*F12*G12) | L12: =IF(J12="","",J12-IF(K12="",0,K12)) | M12: =IF(J12="","",IF(K12="","Unpaid",IF(K12>=J12,"Paid",IF(K12>0,"Partial","Unpaid"))))
A13: 9 | I13: =IFERROR(IF(OR(H13="",B13=""),"",ROUND(H13*switch(B13,"January",4.43,"February",4,"March",4.43,"April",4.33,"May",4.43,"June",4.33,"July",4.43,"August",4.43,"September",4.33,"October",4.43,"November",4.33,"December",4.43,4.33),0)),"") | J13: =IF(OR(I13="",F13="",G13=""),"",I13*F13*G13) | L13: =IF(J13="","",J13-IF(K13="",0,K13)) | M13: =IF(J13="","",IF(K13="","Unpaid",IF(K13>=J13,"Paid",IF(K13>0,"Partial","Unpaid"))))
A14: 10 | I14: =IFERROR(IF(OR(H14="",B14=""),"",ROUND(H14*switch(B14,"January",4.43,"February",4,"March",4.43,"April",4.33,"May",4.43,"June",4.33,"July",4.43,"August",4.43,"September",4.33,"October",4.43,"November",4.33,"December",4.43,4.33),0)),"") | J14: =IF(OR(I14="",F14="",G14=""),"",I14*F14*G14) | L14: =IF(J14="","",J14-IF(K14="",0,K14)) | M14: =IF(J14="","",IF(K14="","Unpaid",IF(K14>=J14,"Paid",IF(K14>0,"Partial","Unpaid"))))
A15: 11 | I15: =IFERROR(IF(OR(H15="",B15=""),"",ROUND(H15*switch(B15,"January",4.43,"February",4,"March",4.43,"April",4.33,"May",4.43,"June",4.33,"July",4.43,"August",4.43,"September",4.33,"October",4.43,"November",4.33,"December",4.43,4.33),0)),"") | J15: =IF(OR(I15="",F15="",G15=""),"",I15*F15*G15) | L15: =IF(J15="","",J15-IF(K15="",0,K15)) | M15: =IF(J15="","",IF(K15="","Unpaid",IF(K15>=J15,"Paid",IF(K15>0,"Partial","Unpaid"))))
A16: 12 | I16: =IFERROR(IF(OR(H16="",B16=""),"",ROUND(H16*switch(B16,"January",4.43,"February",4,"March",4.43,"April",4.33,"May",4.43,"June",4.33,"July",4.43,"August",4.43,"September",4.33,"October",4.43,"November",4.33,"December",4.43,4.33),0)),"") | J16: =IF(OR(I16="",F16="",G16=""),"",I16*F16*G16) | L16: =IF(J16="","",J16-IF(K16="",0,K16)) | M16: =IF(J16="","",IF(K16="","Unpaid",IF(K16>=J16,"Paid",IF(K16>0,"Partial","Unpaid"))))
A17: 13 | I17: =IFERROR(IF(OR(H17="",B17=""),"",ROUND(H17*switch(B17,"January",4.43,"February",4,"March",4.43,"April",4.33,"May",4.43,"June",4.33,"July",4.43,"August",4.43,"September",4.33,"October",4.43,"November",4.33,"December",4.43,4.33),0)),"") | J17: =IF(OR(I17="",F17="",G17=""),"",I17*F17*G17) | L17: =IF(J17="","",J17-IF(K17="",0,K17)) | M17: =IF(J17="","",IF(K17="","Unpaid",IF(K17>=J17,"Paid",IF(K17>0,"Partial","Unpaid"))))
A18: 14 | I18: =IFERROR(IF(OR(H18="",B18=""),"",ROUND(H18*switch(B18,"January",4.43,"February",4,"March",4.43,"April",4.33,"May",4.43,"June",4.33,"July",4.43,"August",4.43,"September",4.33,"October",4.43,"November",4.33,"December",4.43,4.33),0)),"") | J18: =IF(OR(I18="",F18="",G18=""),"",I18*F18*G18) | L18: =IF(J18="","",J18-IF(K18="",0,K18)) | M18: =IF(J18="","",IF(K18="","Unpaid",IF(K18>=J18,"Paid",IF(K18>0,"Partial","Unpaid"))))
A19: 15 | I19: =IFERROR(IF(OR(H19="",B19=""),"",ROUND(H19*switch(B19,"January",4.43,"February",4,"March",4.43,"April",4.33,"May",4.43,"June",4.33,"July",4.43,"August",4.43,"September",4.33,"October",4.43,"November",4.33,"December",4.43,4.33),0)),"") | J19: =IF(OR(I19="",F19="",G19=""),"",I19*F19*G19) | L19: =IF(J19="","",J19-IF(K19="",0,K19)) | M19: =IF(J19="","",IF(K19="","Unpaid",IF(K19>=J19,"Paid",IF(K19>0,"Partial","Unpaid"))))
A20: 16 | I20: =IFERROR(IF(OR(H20="",B20=""),"",ROUND(H20*switch(B20,"January",4.43,"February",4,"March",4.43,"April",4.33,"May",4.43,"June",4.33,"July",4.43,"August",4.43,"September",4.33,"October",4.43,"November",4.33,"December",4.43,4.33),0)),"") | J20: =IF(OR(I20="",F20="",G20=""),"",I20*F20*G20) | L20: =IF(J20="","",J20-IF(K20="",0,K20)) | M20: =IF(J20="","",IF(K20="","Unpaid",IF(K20>=J20,"Paid",IF(K20>0,"Partial","Unpaid"))))
A21: 17 | I21: =IFERROR(IF(OR(H21="",B21=""),"",ROUND(H21*switch(B21,"January",4.43,"February",4,"March",4.43,"April",4.33,"May",4.43,"June",4.33,"July",4.43,"August",4.43,"September",4.33,"October",4.43,"November",4.33,"December",4.43,4.33),0)),"") | J21: =IF(OR(I21="",F21="",G21=""),"",I21*F21*G21) | L21: =IF(J21="","",J21-IF(K21="",0,K21)) | M21: =IF(J21="","",IF(K21="","Unpaid",IF(K21>=J21,"Paid",IF(K21>0,"Partial","Unpaid"))))
A22: 18 | I22: =IFERROR(IF(OR(H22="",B22=""),"",ROUND(H22*switch(B22,"January",4.43,"February",4,"March",4.43,"April",4.33,"May",4.43,"June",4.33,"July",4.43,"August",4.43,"September",4.33,"October",4.43,"November",4.33,"December",4.43,4.33),0)),"") | J22: =IF(OR(I22="",F22="",G22=""),"",I22*F22*G22) | L22: =IF(J22="","",J22-IF(K22="",0,K22)) | M22: =IF(J22="","",IF(K22="","Unpaid",IF(K22>=J22,"Paid",IF(K22>0,"Partial","Unpaid"))))
A23: 19 | I23: =IFERROR(IF(OR(H23="",B23=""),"",ROUND(H23*switch(B23,"January",4.43,"February",4,"March",4.43,"April",4.33,"May",4.43,"June",4.33,"July",4.43,"August",4.43,"September",4.33,"October",4.43,"November",4.33,"December",4.43,4.33),0)),"") | J23: =IF(OR(I23="",F23="",G23=""),"",I23*F23*G23) | L23: =IF(J23="","",J23-IF(K23="",0,K23)) | M23: =IF(J23="","",IF(K23="","Unpaid",IF(K23>=J23,"Paid",IF(K23>0,"Partial","Unpaid"))))
... A54: 50 | I54: =IFERROR(IF(OR(H54="",B54=""),"",ROUND(H54*switch(B54,"January",4.43,"February",4,"March",4.43,"April",4.33,"May",4.43,"June",4.33,"July",4.43,"August",4.43,"September",4.33,"October",4.43,"November",4.33,"December",4.43,4.33),0)),"") | J54: =IF(OR(I54="",F54="",G54=""),"",I54*F54*G54) | L54: =IF(J54="","",J54-IF(K54="",0,K54)) | M54: =IF(J54="","",IF(K54="","Unpaid",IF(K54>=J54,"Paid",IF(K54>0,"Partial","Unpaid"))))
A55: TOTALS | J55: =SUM(J5:J54) -> 56440 | K55: =SUM(K5:K54) -> 0 | L55: =SUM(L5:L54) -> 56440

Sheet Expense Tracker
A1: DAILY EXPENSE TRACKER — Month-wise Expense Log
A2: Log every business expense here. Select Month and Expense Type from dropdowns. Monthly totals are shown at the bottom and in the Dashboard.
A4: # | B4: Month | C4: Date | D4: Expense Type | E4: Description / Notes | F4: Amount (PKR) | G4: Receipt #
A5: 1 | B5: April | C5: 30 | D5: Fuel / Transport
A6: 2 | B6: May | C6: 30 | D6: Milk Purchase
A7: 3 | B7: May | D7: Miscellaneous | F7: 1500
A8: 4 | B8: May | D8: Fuel / Transport | F8: 900
A9: 5 | B9: May | D9: Fuel / Transport | F9: 850
A10: 6 | B10: May | D10: Fuel / Transport | F10: 1500
A11: 7 | B11: May
A12: 8 | B12: May | F12: 850
A13: 9 | B13: May | D13: Fuel / Transport | F13: 500
A14: 10 | B14: May | C14: 13 | D14: Fuel / Transport | F14: 1220 | G14: PETROL 500, Rider 330, Gaon sy anay wala rider 380 Total 1220
A15: 11 | B15: May | D15: Fuel / Transport | F15: 500 | G15: Use by ali
A16: 12 | B16: May | D16: Packaging & Bottles | F16: 2000 | G16: purchase bottles
A17: 13 | B17: May | D17: Fuel / Transport | F17: 500
A18: 14 | B18: May | D18: Fuel / Transport | F18: 500 | G18: 17 may 500 petrol harbanspura and model town
A19: 15 | D19: Fuel / Transport | F19: 1000 | G19: model town gulberg aur gaon
A20: 16 | B20: May | C20: 20 | F20: 1400 | G20: RIDER KO 440, Model Town,Calvary,Johar Town,Bahria PETROL jo mery pas ty un say use kia
A21: 17 | B21: May | C21: 19 | D21: Fuel / Transport | F21: 350 | G21: Baba sy liyay
A22: 18 | B22: May | C22: 21 | D22: Fuel / Transport | F22: 1200 | G22: rider400 aur model town 300 aur bahria 500
A23: 19
A24: 20
A25: 21
A26: 22
A27: 23
A28: 24
A29: 25
A30: 26
A31: 27
A32: 28
A33: 29
A34: 30
... A84: 80
A87: 📊 MONTHLY EXPENSE SUMMARY (Auto-Calculated)
A88: Month | B88: Total Expenses (PKR) | C88: Expense Category Breakdown →
A89: January | B89: =SUMIF(B5:B84,A89,F5:F84) -> 0
A90: February | B90: =SUMIF(B5:B84,A90,F5:F84) -> 0
A91: March | B91: =SUMIF(B5:B84,A91,F5:F84) -> 0
A92: April | B92: =SUMIF(B5:B84,A92,F5:F84) -> 0
...

Sheet Sheet1
A1: House No | B1: Date | C1: Price | D1: Quantity
A2: G2 house Cantt | B2: 46148 | C2: 430 | D2: 1L
A3: G2 house Cantt | B3: 46152 | C3: 430 | D3: 1L | E3: petrol 430
A4: Bahria | B4: 46153 | C4: 430 | D4: 1L
A5: Izmir town | B5: 46153 | C5: 330 | D5: 1 L | E5: petrol 850 | F5: 570 | G5: 46153
A6: Askari 11 | B6: 46153 | C6: 660 | D6: 2 L
A7: Bahria Sector D | B7: 46154 | C7: 860 | D7: 2 L | E7: petrol 500 | F7: 360 | G7: 46154
A8: Bahria Sector B | B8: 46155 | C8: 2580 | D8: 6 L | E8: 2000 bottles, 330 rider jo dood laya, 320 Ama wala rider, 150 ali wala rider, 500 petrol, aglay din ama wala rider 350, aur 18 may ama wala rider 250 phir 19 may ama wala rider 256
A9: 52 E Model Town | B9: 46155 | C9: 760 | D9: 2 L | F9: 280 | G9: 46155
A10: Phase 5 | B10: 46155 | C10: 660 | D10: 2L | E10: 500 use by Ali
A11: 33 D model town | B11: 46158 | C11: 860 | D11: 2 L | E11: Yah ali ky pas hi haan
A12: Gulberg | B12: 46160 | C12: 430 | D12: 1 L | E12: Ali ky pas add 1000 in expense
A13: Model Town R block | B13: 46160 | C13: 760 | D13: 2 L | E13: Ali ky pas
A14: Bahria Sector B | B14: 46160 | C14: 1720 | D14: 4L | E14: Ali ky pas
A15: 91 h3 johar town | B15: 46162 | C15: 330 | D15: 1 L | E15: IN EXPENSE
A16: Gulberg | B16: 46163 | C16: 430 | D16: 1L | E16: 250 PETROL
